PS C:\Users\team\Desktop\Annotation_Emotion\emot-ann> python3 .\video.py
* Running on local URL:  http://127.0.0.1:7860
* To create a public link, set `share=True` in `launch()`.
Copied video to: C:\Users\team\AppData\Local\Temp\tmp8fg9wlu7\working_1023 Emotion Discussion Task.MP4
Copied video to: C:\Users\team\AppData\Local\Temp\tmp8fg9wlu7\working_1023 Emotion Discussion Task.MP4
Successfully wrote 149 frames to C:\Users\team\AppData\Local\Temp\tmp8fg9wlu7\clip_001.mp4
Successfully wrote 149 frames to C:\Users\team\AppData\Local\Temp\tmp8fg9wlu7\clip_002.mp4
Successfully wrote 149 frames to C:\Users\team\AppData\Local\Temp\tmp8fg9wlu7\clip_003.mp4
Successfully wrote 149 frames to C:\Users\team\AppData\Local\Temp\tmp8fg9wlu7\clip_004.mp4
Successfully wrote 149 frames to C:\Users\team\AppData\Local\Temp\tmp8fg9wlu7\clip_005.mp4
Successfully wrote 149 frames to C:\Users\team\AppData\Local\Temp\tmp8fg9wlu7\clip_006.mp4
Successfully wrote 149 frames to C:\Users\team\AppData\Local\Temp\tmp8fg9wlu7\clip_007.mp4
Successfully wrote 149 frames to C:\Users\team\AppData\Local\Temp\tmp8fg9wlu7\clip_008.mp4
Successfully wrote 149 frames to C:\Users\team\AppData\Local\Temp\tmp8fg9wlu7\clip_009.mp4
Successfully wrote 149 frames to C:\Users\team\AppData\Local\Temp\tmp8fg9wlu7\clip_010.mp4
Successfully wrote 149 frames to C:\Users\team\AppData\Local\Temp\tmp8fg9wlu7\clip_011.mp4
Successfully wrote 149 frames to C:\Users\team\AppData\Local\Temp\tmp8fg9wlu7\clip_012.mp4
Successfully wrote 10 frames to C:\Users\team\AppData\Local\Temp\tmp8fg9wlu7\clip_013.mp4
Exception in callback _ProactorBasePipeTransport._call_connection_lost()
handle: <Handle _ProactorBasePipeTransport._call_connection_lost()>
Traceback (most recent call last):
  File "C:\Program Files\WindowsApps\PythonSoftwareFoundation.Python.3.13_3.13.2544.0_x64__qbz5n2kfra8p0\Lib\asyncio\events.py", line 89, in _run
    self._context.run(self._callback, *self._args)
    ~~~~~~~~~~~~~~~~~^^^^^^^^^^^^^^^^^^^^^^^^^^^^^
  File "C:\Program Files\WindowsApps\PythonSoftwareFoundation.Python.3.13_3.13.2544.0_x64__qbz5n2kfra8p0\Lib\asyncio\proactor_events.py", line 165, in _call_connection_lost
    self._sock.shutdown(socket.SHUT_RDWR)
    ~~~~~~~~~~~~~~~~~~~^^^^^^^^^^^^^^^^^^
ConnectionResetError: [WinError 10054] An existing connection was forcibly closed by the remote host