Traceback (most recent call last):
  File "C:\Program Files\WindowsApps\PythonSoftwareFoundation.Python.3.13_3.13.2544.0_x64__qbz5n2kfra8p0\Lib\asyncio\events.py", line 89, in _run
    self._context.run(self._callback, *self._args)
    ~~~~~~~~~~~~~~~~~^^^^^^^^^^^^^^^^^^^^^^^^^^^^^
  File "C:\Program Files\WindowsApps\PythonSoftwareFoundation.Python.3.13_3.13.2544.0_x64__qbz5n2kfra8p0\Lib\asyncio\proactor_events.py", line 165, in _call_connection_lost
    self._sock.shutdown(socket.SHUT_RDWR)
    ~~~~~~~~~~~~~~~~~~~^^^^^^^^^^^^^^^^^^
ConnectionResetError: [WinError 10054] An existing connection was forcibly closed by the remote host